2025-08-17 07:51:21,139 [INFO] Step-1: Folder created: uploads/02a3c161-c5a8-4c56-9832-6e2af5ce108e
2025-08-17 07:51:21,142 [INFO] Using Python executable: venv/bin/python3
2025-08-17 07:51:21,142 [INFO] Step-2: File sent {'question.txt': 'uploads/02a3c161-c5a8-4c56-9832-6e2af5ce108e/question.txt'}
2025-08-17 07:51:21,142 [INFO] 🤖 Step-1: Getting scrap code and metadata from llm. Tries count = 0
2025-08-17 07:51:27,627 [INFO] 🤖 Step-1: Successfully parsed response from LLM.
2025-08-17 07:51:27,627 [INFO] 💻 Step-3: Entering loop
2025-08-17 07:51:27,627 [INFO] 💻 Loop-1: Running LLM code.
2025-08-17 07:51:30,323 [INFO] ✅💻 Loop-1: Code executed successfully.
2025-08-17 07:51:30,323 [INFO] 🤖 Loop-1: Inside Loop LLM call.
2025-08-17 07:51:38,560 [INFO] 💻 Loop-2: Running LLM code.
2025-08-17 07:51:41,998 [INFO] ✅💻 Loop-2: Code executed successfully.
2025-08-17 07:51:41,998 [INFO] 🤖 Loop-2: Inside Loop LLM call.
2025-08-17 07:52:12,056 [INFO] 💻 Loop-3: Running LLM code.
2025-08-17 07:52:13,976 [INFO] ✅💻 Loop-3: Code executed successfully.
2025-08-17 07:52:13,976 [INFO] 🤖 Loop-3: Inside Loop LLM call.
2025-08-17 07:52:29,111 [INFO] 💻 Step-6: Running final code.
2025-08-17 07:52:29,837 [ERROR] ❌💻 Step-6: Final code execution failed: error: Traceback (most recent call last): File "/home/kas4453/kas/tds-project-2/venv/lib/python3.13/site-packages/pandas/core/indexes/base.py", line 3812, in get_loc return self._engine.get_loc(casted_key) ~~~~~~~~~~~~~~~~~~~~^^^^^^^^^^^^ File "pandas/_libs/index.pyx", line 167, in pandas._libs.index.IndexEngine.get_loc File "pandas/_libs/index.pyx", line 196, in pandas._libs.index.IndexEngine.get_loc File "pandas/_libs/hashtable_class_helper.pxi", line 7088, in pandas._libs.hashtable.PyObjectHashTable.get_item File "pandas/_libs/hashtable_class_helper.pxi", line 7096, in pandas._libs.hashtable.PyObjectHashTable.get_item KeyError: 'Worldwide gross' The above exception was the direct cause of the following exception: Traceback (most recent call last): File "/home/kas4453/kas/tds-project-2/uploads/02a3c161-c5a8-4c56-9832-6e2af5ce108e/job_/script.py", line 65, in <module> solve_and_save() ~~~~~~~~~~~~~~^^ File "/home/kas4453/kas/tds-project-2/uploads/02a3c161-c5a8-4c56-9832-6e2af5ce108e/job_/script.py", line 25, in solve_and_save df['Worldwide gross'] = df['Worldwide gross'].apply(clean_currency) ~~^^^^^^^^^^^^^^^^^^^ File "/home/kas4453/kas/tds-project-2/venv/lib/python3.13/site-packages/pandas/core/frame.py", line 4107, in __getitem__ indexer = self.columns.get_loc(key) File "/home/kas4453/kas/tds-project-2/venv/lib/python3.13/site-packages/pandas/core/indexes/base.py", line 3819, in get_loc raise KeyError(key) from err KeyError: 'Worldwide gross'
2025-08-17 07:52:29,837 [ERROR] ❌📁 Step-7: result.json not found. Checking for result.txt.
2025-08-17 07:52:29,837 [ERROR] ❌📁 result.txt not found.
